<?xml version="1.0" encoding="utf-8"?>


<robot name="MacBot"> 
    <!-- cheers macleay for the robot -->

    <link name="link0"> ... </link>
    <link name="link1"> ... </link>
    <link name="link2"> ... </link>

    <joint name="joint0" type="revolute"> 
        <parent link="link0" />
        <child link="link1" />
    </joint>

    <joint name="joint1" type="revolute"> ... </joint>
        <parent link="link1" />
        <child link="link2" />
    </joint>

    <joint name="joint2" type="revolute"> 
        <parent link="link2"/>
        <child link="link3"/>
    </joint>

</robot>
